2020-03-13 01:40:18,374 ERROR django.request Internal Server Error: /api/campaign/
Traceback (most recent call last):
  File "/home/ltf/Documents/univeristy_gofundme/lib/python3.6/site-packages/django/core/handlers/exception.py", line 34, in inner
    response = get_response(request)
  File "/home/ltf/Documents/univeristy_gofundme/lib/python3.6/site-packages/django/core/handlers/base.py", line 115, in _get_response
    response = self.process_exception_by_middleware(e, request)
  File "/home/ltf/Documents/univeristy_gofundme/lib/python3.6/site-packages/django/core/handlers/base.py", line 113, in _get_response
    response = wrapped_callback(request, *callback_args, **callback_kwargs)
  File "/home/ltf/Documents/univeristy_gofundme/lib/python3.6/site-packages/django/views/decorators/csrf.py", line 54, in wrapped_view
    return view_func(*args, **kwargs)
  File "/home/ltf/Documents/univeristy_gofundme/lib/python3.6/site-packages/django/views/generic/base.py", line 71, in view
    return self.dispatch(request, *args, **kwargs)
  File "/home/ltf/Documents/univeristy_gofundme/lib/python3.6/site-packages/rest_framework/views.py", line 505, in dispatch
    response = self.handle_exception(exc)
  File "/home/ltf/Documents/univeristy_gofundme/lib/python3.6/site-packages/rest_framework/views.py", line 465, in handle_exception
    self.raise_uncaught_exception(exc)
  File "/home/ltf/Documents/univeristy_gofundme/lib/python3.6/site-packages/rest_framework/views.py", line 476, in raise_uncaught_exception
    raise exc
  File "/home/ltf/Documents/univeristy_gofundme/lib/python3.6/site-packages/rest_framework/views.py", line 502, in dispatch
    response = handler(request, *args, **kwargs)
  File "/home/ltf/Documents/GITLAB/University_Fuding/uWinFundMe_backend/src/uni_gofundme/campaign/api/views.py", line 95, in post
    serializer.save()
  File "/home/ltf/Documents/univeristy_gofundme/lib/python3.6/site-packages/rest_framework/serializers.py", line 212, in save
    self.instance = self.create(validated_data)
  File "/home/ltf/Documents/GITLAB/University_Fuding/uWinFundMe_backend/src/uni_gofundme/campaign/api/serializers.py", line 112, in create
    obj['created_by_id'] = self.created_or_modified_by()
  File "/home/ltf/Documents/GITLAB/University_Fuding/uWinFundMe_backend/src/uni_gofundme/campaign/api/serializers.py", line 53, in created_or_modified_by
    username = request.session['username']
  File "/home/ltf/Documents/univeristy_gofundme/lib/python3.6/site-packages/django/contrib/sessions/backends/base.py", line 64, in __getitem__
    return self._session[key]
KeyError: 'username'
